Workbook
Name Company_name: Dashboard!$D$4
Name currency: Dashboard!$D$6
Name LHY: Dashboard!$D$8
Name ticker: Dashboard!$D$10

Sheet Dashboard
C4: Company name | D4: Coca-Cola Consolidated, Inc. (COKE)
C6: Currency | D6: in thousands, except per share data
C8: LHY | D8: 45657
C10: Ticker | D10: COKE
J13: ctrl + F3

Sheet Income Statement
B2: =Company_name -> Coca-Cola Consolidated, Inc. (COKE)
B3: Income Statement | D3: Historical | G3: Forcasted
B4: =currency -> in thousands, except per share data | D4: =EDATE(E4,-12) -> 44926 | E4: =EDATE(F4,-12) -> 45291 | F4: =LHY -> 45657 | G4: =EDATE(F4,12) -> 46022 | H4: =EDATE(G4,12) -> 46387 | I4: =EDATE(H4,12) -> 46752
F6: Normal | G6: =IF(F6="Normal",1,IF(F6="Best",2,3)) -> 1
C7: Net sales | D7: 6200957 | E7: 6653858 | F7: 6899716 | G7: 7190424.1 | H7: 7497642.6 | I7: ='Revenue Driver'!L33 -> 7822069.8
C8: Cost of sales | D8: 3923003 | E8: 4055147 | F8: 4146537 | G8: =CHOOSE($G$6,'Cost Driver'!G10,'Cost Driver'!G11,'Cost Driver'!G12)*'Income Statement'!G7 -> 4417460.7 | H8: =CHOOSE($G$6,'Cost Driver'!H10,'Cost Driver'!H11,'Cost Driver'!H12)*'Income Statement'!H7 -> 4606201.4 | I8: =CHOOSE($G$6,'Cost Driver'!I10,'Cost Driver'!I11,'Cost Driver'!I12)*'Income Statement'!I7 -> 4805514.3
C9: Gross profit | D9: 2277954 | E9: 2598711 | F9: 2753179 | G9: =G7-G8 -> 2772963.4 | H9: =H7-H8 -> 2891441.2 | I9: =I7-I8 -> 3016555.5
C10: Selling, delivery and administrative expenses | D10: 1636907 | E10: 1764260 | F10: 1832829 | G10: =CHOOSE($G$6,'Cost Driver'!G15,'Cost Driver'!G16,'Cost Driver'!G17)*'Income Statement'!G7 -> 1904895 | H10: =CHOOSE($G$6,'Cost Driver'!H15,'Cost Driver'!H16,'Cost Driver'!H17)*'Income Statement'!H7 -> 1986283.6 | I10: =CHOOSE($G$6,'Cost Driver'!I15,'Cost Driver'!I16,'Cost Driver'!I17)*'Income Statement'!I7 -> 2072231.2
C11: Income from operations | D11: 641047 | E11: 834451 | F11: 920350 | G11: =G9-G10 -> 868068.42 | H11: =H9-H10 -> 905157.56 | I11: =I9-I10 -> 944324.24
C12: Interest expense (income), net | D12: 24792 | E12: -918 | F12: 1848 | G12: =G7*Assumptions!G9 -> 9893.9387 | H12: =H7*Assumptions!H9 -> 3763.4673 | I12: =I7*Assumptions!I9 -> 5594.8103
C13: Mark-to-market on acquisition related contingent consideration | D13: 32301 | E13: 159354 | F13: 59166 | G13: =G7*Assumptions!G10 -> 90439.437 | H13: =H7*Assumptions!H10 -> 112719.58 | I13: =I7*Assumptions!I10 -> 94352.152
C14: Pension plan settlement expense | D14: 0 | E14: 112796 | F14: 0 | G14: =G7*Assumptions!G11 -> 0 | H14: =H7*Assumptions!H11 -> 0 | I14: =I7*Assumptions!I11 -> 0
C15: Other expense, net | D15: 8867 | E15: 5738 | F15: 2682 | G15: =G7*Assumptions!G12 -> 6425.8641 | H15: =H7*Assumptions!H12 -> 5360.1601 | I15: =I7*Assumptions!I12 -> 5207.6578
C16: Income before taxes | D16: 575087 | E16: 557481 | F16: 856654 | G16: =G11-SUM(G12:G15) -> 761309.18 | H16: =H11-SUM(H12:H15) -> 783314.35 | I16: =I11-SUM(I12:I15) -> 839169.62
C17: Income tax expense | D17: 144929 | E17: 149106 | F17: 223529 | G17: =G16*Assumptions!G13 -> 198044.12 | H17: =H16*Assumptions!H13 -> 205889.67 | I17: =I16*Assumptions!I13 -> 219278.7
C18: Tax Rate | D18: =D17/D16 -> 0.2520123 | E18: =E17/E16 -> 0.26746382 | F18: =F17/F16 -> 0.26093265 | G18: =F18 -> 0.26093265 | H18: =G18 -> 0.26093265 | I18: =H18 -> 0.26093265
C19: Net income | D19: 430158 | E19: 408375 | F19: 633125 | G19: =G16-G17 -> 563265.06 | H19: =H16-H17 -> 577424.68 | I19: =I16-I17 -> 619890.91
C21: Basic net income per share:
C22: Common Stock | D22: =D19/D36 -> 4.0228 | E22: =E19/E36 -> 3.9210274 | F22: =F19/F36 -> 6.286615 | G22: =G19/G36 -> 5.5929407 | H22: =H19/H36 -> 5.7335387 | I22: =I19/I36 -> 6.1552072
C23: Weighted average number of Common Stock shares outstanding | D23: 8117 | E23: 8369 | F23: 8035 | G23: =F23 -> 8035 | H23: =G23 -> 8035 | I23: =H23 -> 8035
C25: Class B Common Stock | D25: =D19/D36 -> 4.0228 | E25: =E19/E36 -> 3.9210274 | F25: =F19/F36 -> 6.286615 | G25: =G19/G36 -> 5.5929407 | H25: =H19/H36 -> 5.7335387 | I25: =I19/I36 -> 6.1552072
C26: Weighted average number of Class B Common Stock shares outstanding | D26: 1257 | E26: 1005 | F26: 1005 | G26: =F26 -> 1005 | H26: =G26 -> 1005 | I26: =H26 -> 1005
C28: Diluted net income per share:
C29: Common Stock | D29: =D19/D36 -> 4.0228 | E29: =E19/E36 -> 3.9210274 | F29: =F19/F36 -> 6.286615 | G29: =G19/G36 -> 5.5929407 | H29: =H19/H36 -> 5.7335387 | I29: =I19/I36 -> 6.1552072
C30: Weighted average number of Common Stock shares outstanding – assuming dilution | D30: 9405 | E30: 9392 | F30: 9053 | G30: =F30 -> 9053 | H30: =G30 -> 9053 | I30: =H30 -> 9053
C32: Class B Common Stock | D32: =D19/D36 -> 4.0228 | E32: =E19/E36 -> 3.9210274 | F32: =F19/F36 -> 6.286615 | G32: =G19/G36 -> 5.5929407 | H32: =H19/H36 -> 5.7335387 | I32: =I19/I36 -> 6.1552072
C33: Weighted average number of Class B Common Stock shares outstanding – assuming dilution | D33: 1288 | E33: 1023 | F33: 1018 | G33: =F33 -> 1018 | H33: =G33 -> 1018 | I33: =H33 -> 1018
C34: Total Outstanding | D34: =D30+D33 -> 10693 | E34: =E30+E33 -> 10415 | F34: =F30+F33 -> 10071 | G34: =G30+G33 -> 10071 | H34: =H30+H33 -> 10071 | I34: =I30+I33 -> 10071
C36: Split Shares 1:10 | D36: =D34*10 -> 106930 | E36: =E34*10 -> 104150 | F36: =F34*10 -> 100710 | G36: =G34*10 -> 100710 | H36: =H34*10 -> 100710 | I36: =I34*10 -> 100710
C106: Previous year amount*(1+3%)

Sheet Sheet3
G5: =EDATE(H5,-12) -> 45291 | H5: =LHY -> 45657 | I5: =EDATE(H5,12) -> 46022 | J5: =EDATE(I5,12) -> 46387
F6: Net sales | G6: 6653858 | H6: 6899716 | I6: 7190424.1 | J6: 7497642.6

Sheet Balance Sheet
B2: =Company_name -> Coca-Cola Consolidated, Inc. (COKE)
B3: Balance Sheet | E3: Historical | H3: Forcasted
B4: =currency -> in thousands, except per share data | D4: =EDATE(E4,-12) -> 44561 | E4: =EDATE(F4,-12) -> 44926 | F4: =EDATE(G4,-12) -> 45291 | G4: =LHY -> 45657 | H4: =EDATE(G4,12) -> 46022 | I4: =EDATE(H4,12) -> 46387 | J4: =EDATE(I4,12) -> 46752
C7: ASSETS
C8: Current Assets:
C9: Cash and cash equivalents | D9: 142314 | E9: 197648 | F9: 635269 | G9: 1135824 | H9: ='Cash Flow Statement'!G45 -> 1334505.1 | I9: ='Cash Flow Statement'!H45 -> 1585336.9 | J9: ='Cash Flow Statement'!I45 -> 1896400.9
C10: Short-term investments | D10: 0 | E10: 0 | F10: 0 | G10: 301210 | H10: ='Income Statement'!G7*Assumptions!G17 -> 104633.66 | I10: ='Income Statement'!H7*Assumptions!H17 -> 145472.33 | J10: ='Income Statement'!I7*Assumptions!I17 -> 202355.99
C11: Accounts receivable, trade | D11: 472270 | E11: 532047 | F11: 555933 | G11: 567653 | H11: ='Income Statement'!G7*Assumptions!G18 -> 603092.51 | I11: ='Income Statement'!H7*Assumptions!H18 -> 624045.82 | J11: ='Income Statement'!I7*Assumptions!I18 -> 650218.96
C12: Allowance for doubtful accounts | D12: -17336 | E12: -16119 | F12: -16060 | G12: -14674 | H12: ='Income Statement'!G7*Assumptions!G19 -> -17112.799 | I12: ='Income Statement'!H7*Assumptions!H19 -> -17295.398 | J12: ='Income Statement'!I7*Assumptions!I19 -> -17765.16
C13: Accounts receivable from The Coca-Cola Company | D13: 57737 | E13: 35786 | F13: 51936 | G13: 89871 | H13: ='Income Statement'!G7*Assumptions!G20 -> 63759.312 | I13: ='Income Statement'!H7*Assumptions!H20 -> 74221.584 | J13: ='Income Statement'!I7*Assumptions!I20 -> 82892.806
C14: Accounts receivable, other | D14: 33878 | E14: 54631 | F14: 67533 | G14: 40692 | H14: ='Income Statement'!G7*Assumptions!G21 -> 59577.879 | I14: ='Income Statement'!H7*Assumptions!H21 -> 60812.903 | J14: ='Income Statement'!I7*Assumptions!I21 -> 58129.179
C15: Inventories | D15: 302851 | E15: 347545 | F15: 321932 | G15: 330395 | H15: ='Income Statement'!G8*Assumptions!G22 -> 364675.82 | I15: ='Income Statement'!H8*Assumptions!H22 -> 370985.76 | J15: ='Income Statement'!I8*Assumptions!I22 -> 388883.86
C16: Prepaid expenses and other current assets | D16: 78068 | E16: 94263 | F16: 88585 | G16: 96331 | H16: ='Income Statement'!G7*Assumptions!G23 -> 101807.49 | I16: ='Income Statement'!H7*Assumptions!H23 -> 103551.64 | J16: ='Income Statement'!I7*Assumptions!I23 -> 109330.57
C17: Assets held for sale | D17: 6880 | E17: 0 | F17: 0 | G17: 0 | H17: ='Income Statement'!G7*Assumptions!G24 -> 0 | I17: ='Income Statement'!H7*Assumptions!H24 -> 0 | J17: ='Income Statement'!I7*Assumptions!I24 -> 0
C18: Total current assets | D18: 1076662 | E18: 1245801 | F18: 1705128 | G18: 2547302 | H18: =SUM(H9:H17) -> 2614939 | I18: =SUM(I9:I17) -> 2947131.5 | J18: =SUM(J9:J17) -> 3370447.1
C19: Property, plant and equipment, net | D19: 1030688 | E19: 1183730 | F19: 1320563 | G19: 1505267 | H19: =FAM!H91 -> 1741772.3 | I19: =FAM!I91 -> 1978097.4 | J19: =FAM!J91 -> 2215034.4
C20: Right-of-use assets - operating leases | D20: 139877 | E20: 140588 | F20: 122708 | G20: 112351 | H20: =G20 -> 112351 | I20: =H20 -> 112351 | J20: =I20 -> 112351
C21: Leased property under financing leases, net | D21: 64211 | E21: 6431 | F21: 4785 | G21: 3138 | H21: =G21 -> 3138 | I21: =H21 -> 3138 | J21: =I21 -> 3138
C22: Other assets | D22: 120486 | E22: 115892 | F22: 145213 | G22: 181048 | H22: ='Income Statement'!G7*Assumptions!G25 -> 159994.54 | I22: ='Income Statement'!H7*Assumptions!H25 -> 175731.89 | J22: ='Income Statement'!I7*Assumptions!I25 -> 187545.24
C23: Goodwill | D23: 165903 | E23: 165903 | F23: 165903 | G23: 165903 | H23: =G23 -> 165903 | I23: =H23 -> 165903 | J23: =I23 -> 165903
C24: Distribution agreements, net | D24: 836777 | E24: 842035 | F24: 817143 | G24: 792252 | H24: ='Income Statement'!G7*Assumptions!G26 -> 895021.79 | I24: ='Income Statement'!H7*Assumptions!H26 -> 904978.92 | J24: ='Income Statement'!I7*Assumptions!I26 -> 938647.81
C25: Customer lists, net | D25: 10966 | E25: 9165 | F25: 7499 | G25: 5878 | H25: ='Income Statement'!G7*Assumptions!G27 -> 8285.6027 | I25: ='Income Statement'!H7*Assumptions!H27 -> 7825.6524 | J25: ='Income Statement'!I7*Assumptions!I27 -> 7947.1661
C26: Total assets | D26: 3445570 | E26: 3709545 | F26: 4288942 | G26: 5313139 | H26: =SUM(H18:H25) -> 5701405.2 | I26: =SUM(I18:I25) -> 6295157.4 | J26: =SUM(J18:J25) -> 7001013.7
C28: LIABILITIES AND EQUITY
C29: Current Liabilities:
C30: Current portion of obligations under operating leases | D30: 22048 | E30: 27635 | F30: 26194 | G30: 23257 | H30: =G30 -> 23257 | I30: =H30 -> 23257 | J30: =I30 -> 23257
C31: Current portion of obligations under financing leases | D31: 6060 | E31: 2303 | F31: 2487 | G31: 2685 | H31: =G31 -> 2685 | I31: =H31 -> 2685 | J31: =I31 -> 2685
C32: Accounts payable, trade | D32: 319318 | E32: 351729 | F32: 383562 | G32: 334878 | H32: ='Income Statement'!G8*Assumptions!G30 -> 390217.05 | I32: ='Income Statement'!H8*Assumptions!H30 -> 404858.22 | J32: ='Income Statement'!I8*Assumptions!I30 -> 411656.69
C33: Accounts payable to The Coca-Cola Company | D33: 145671 | E33: 162783 | F33: 139499 | G33: 187271 | H33: ='Income Statement'!G8*Assumptions!G31 -> 178256.61 | I33: ='Income Statement'!H8*Assumptions!H31 -> 184119.76 | J33: ='Income Statement'!I8*Assumptions!I31 -> 201011.63
C34: Other accrued liabilities | D34: 226769 | E34: 198300 | F34: 237994 | G34: 246687 | H34: ='Income Statement'!G7*Assumptions!G32 -> 248069.55 | I34: ='Income Statement'!H7*Assumptions!H32 -> 264969.24 | J34: ='Income Statement'!I7*Assumptions!I32 -> 275320.01
C35: Accrued compensation | D35: 110894 | E35: 126921 | F35: 146932 | G35: 168692 | H35: ='Income Statement'!G7*Assumptions!G33 -> 160584.5 | I35: ='Income Statement'!H7*Assumptions!H33 -> 172107.02 | J35: ='Income Statement'!I7*Assumptions!I33 -> 181829.35
C36: Accrued interest payable | D36: 4096 | E36: 2677 | F36: 0 | G36: 0 | H36: ='Income Statement'!G7*Assumptions!G34 -> 0 | I36: ='Income Statement'!H7*Assumptions!H34 -> 0 | J36: ='Income Statement'!I7*Assumptions!I34 -> 0
C37: Dividends payable | D37: 0 | E37: 32808 | F37: 154666 | G37: 0 | H37: ='Income Statement'!G7*Assumptions!G35 -> 0 | I37: ='Income Statement'!H7*Assumptions!H35 -> 0 | J37: ='Income Statement'!I7*Assumptions!I35 -> 0
C38: Current portion of debt | D38: 0 | E38: 0 | F38: 0 | G38: 349699 | H38: =G38 -> 349699 | I38: =H38 -> 349699 | J38: =I38 -> 349699
C39: Total current liabilities | D39: 834856 | E39: 905156 | F39: 1091334 | G39: 1313169 | H39: =SUM(H30:H38) -> 1352768.7 | I39: =SUM(I30:I38) -> 1401695.2 | J39: =SUM(J30:J38) -> 1445458.7
C40: Deferred income taxes | D40: 136432 | E40: 150222 | F40: 128435 | G40: 132941 | H40: ='Income Statement'!G7*Assumptions!G36 -> 150508.89 | I40: ='Income Statement'!H7*Assumptions!H36 -> 148707.72 | J40: ='Income Statement'!I7*Assumptions!I36 -> 156528.45
C41: Pension and postretirement benefit obligations | D41: 93391 | E41: 60323 | F41: 60614 | G41: 58502 | H41: ='Income Statement'!G7*Assumptions!G37 -> 65472.446 | I41: ='Income Statement'!H7*Assumptions!H37 -> 66714.042 | J41: ='Income Statement'!I7*Assumptions!I37 -> 69049.08
C42: Other liabilities | D42: 758610 | E42: 753357 | F42: 866499 | G42: 859559 | H42: ='Income Statement'!G7*Assumptions!G38 -> 901905.41 | I42: ='Income Statement'!H7*Assumptions!H38 -> 950289.73 | J42: ='Income Statement'!I7*Assumptions!I38 -> 982335.92
C43: Noncurrent portion of obligations under operating leases | D43: 122046 | E43: 118763 | F43: 102271 | G43: 92362 | H43: =G43 -> 92362 | I43: =H43 -> 92362 | J43: =I43 -> 92362
C44: Noncurrent portion of obligations under financing leases | D44: 65006 | E44: 7519 | F44: 5032 | G44: 2346 | H44: =G44 -> 2346 | I44: =H44 -> 2346 | J44: =I44 -> 2346
...

Sheet Cash Flow Statement
B2: =Company_name -> Coca-Cola Consolidated, Inc. (COKE)
B3: Cash Flow Statement | D3: Historical | G3: Forcasted
B4: =currency -> in thousands, except per share data | D4: =EDATE(E4,-12) -> 44926 | E4: =EDATE(F4,-12) -> 45291 | F4: =LHY -> 45657 | G4: =EDATE(F4,12) -> 46022 | H4: =EDATE(G4,12) -> 46387 | I4: =EDATE(H4,12) -> 46752
C7: Cash Flows from Operating Activities:
C8: Net income | D8: 430158 | E8: 408375 | F8: 633125 | G8: ='Income Statement'!G19 -> 563265.06 | H8: ='Income Statement'!H19 -> 577424.68 | I8: ='Income Statement'!I19 -> 619890.91
C9: Adjustments to reconcile net income to net cash provided by operating activities:
C10: Depreciation expense from property, plant and equipment and financing leases | D10: 147962 | E10: 153472 | F10: 170343 | G10: =FAM!H86 -> 110645.85 | H10: =FAM!I86 -> 125658.38 | I10: =FAM!J86 -> 140709.77
C11: Amortization of intangible assets and deferred proceeds, net | D11: 23628 | E11: 23494 | F11: 23448
C12: Fair value adjustment of acquisition related contingent consideration | D12: 32301 | E12: 159354 | F12: 59166
C13: Loss on sale of property, plant and equipment | D13: 5642 | E13: 7181 | F13: 3168
C14: Deferred income taxes | D14: 8977 | E14: -49021 | F14: 2529 | G14: ='Balance Sheet'!H40-'Balance Sheet'!G40 -> 17567.892 | H14: ='Balance Sheet'!I40-'Balance Sheet'!H40 -> -1801.1692 | I14: ='Balance Sheet'!J40-'Balance Sheet'!I40 -> 7820.7243
C15: Amortization of debt costs | D15: 1012 | E15: 991 | F15: 2310
C16: Pension plan settlement expense | D16: 0 | E16: 112796 | F16: 0 | G16: ='Balance Sheet'!H41-'Balance Sheet'!G41 -> 6970.4463 | H16: ='Balance Sheet'!I41-'Balance Sheet'!H41 -> 1241.596 | I16: ='Balance Sheet'!J41-'Balance Sheet'!I41 -> 2335.0378
C17: Deferred payroll taxes under CARES Act | D17: -18739 | E17: 0 | F17: 0
C18: Change in current assets less current liabilities | D18: -74784 | E18: 29138 | F18: -3774 | G18: ='Balance Sheet'!G11-'Balance Sheet'!H11+'Balance Sheet'!G12-'Balance Sheet'!H12+'Balance Sheet'!G13-'Balance Sheet'!H13+'Balance Sheet'!G14-'Balance Sheet'!H14+'Balance Sheet'!G15-'Balance Sheet'!H15+'Balance Sheet'!G16-'Balance Sheet'!H16+'Balance Sheet'!H32-'Balance Sheet'!G32+'Balance Sheet'!H33-'Balance Sheet'!G33+'Balance Sheet'!H34-'Balance Sheet'!G34+'Balance Sheet'!H35-'Balance Sheet'!G35 -> -25932.499 | H18: ='Balance Sheet'!H11-'Balance Sheet'!I11+'Balance Sheet'!H12-'Balance Sheet'!I12+'Balance Sheet'!H13-'Balance Sheet'!I13+'Balance Sheet'!H14-'Balance Sheet'!I14+'Balance Sheet'!H15-'Balance Sheet'!I15+'Balance Sheet'!H16-'Balance Sheet'!I16+'Balance Sheet'!I32-'Balance Sheet'!H32+'Balance Sheet'!I33-'Balance Sheet'!H33+'Balance Sheet'!I34-'Balance Sheet'!H34+'Balance Sheet'!I35-'Balance Sheet'!H35 -> 8404.4325 | I18: ='Balance Sheet'!I11-'Balance Sheet'!J11+'Balance Sheet'!I12-'Balance Sheet'!J12+'Balance Sheet'!I13-'Balance Sheet'!J13+'Balance Sheet'!I14-'Balance Sheet'!J14+'Balance Sheet'!I15-'Balance Sheet'!J15+'Balance Sheet'!I16-'Balance Sheet'!J16+'Balance Sheet'!J32-'Balance Sheet'!I32+'Balance Sheet'!J33-'Balance Sheet'!I33+'Balance Sheet'!J34-'Balance Sheet'!I34+'Balance Sheet'!J35-'Balance Sheet'!I35 -> -11604.463
C19: Change in other noncurrent assets | D19: 31779 | E19: 12708 | F19: 8904 | G19: ='Balance Sheet'!G22-'Balance Sheet'!H22+'Balance Sheet'!G23-'Balance Sheet'!H23+'Balance Sheet'!G24-'Balance Sheet'!H24+'Balance Sheet'!G25-'Balance Sheet'!H25 -> -84123.938 | H19: ='Balance Sheet'!H22-'Balance Sheet'!I22+'Balance Sheet'!H23-'Balance Sheet'!I23+'Balance Sheet'!H24-'Balance Sheet'!I24+'Balance Sheet'!H25-'Balance Sheet'!I25 -> -25234.53 | I19: ='Balance Sheet'!I22-'Balance Sheet'!J22+'Balance Sheet'!I23-'Balance Sheet'!J23+'Balance Sheet'!I24-'Balance Sheet'!J24+'Balance Sheet'!I25-'Balance Sheet'!J25 -> -45603.746
C20: Change in other noncurrent liabilities | D20: -33430 | E20: -47798 | F20: -22862 | G20: ='Balance Sheet'!H42-'Balance Sheet'!G42 -> 42346.412 | H20: ='Balance Sheet'!I42-'Balance Sheet'!H42 -> 48384.32 | I20: ='Balance Sheet'!J42-'Balance Sheet'!I42 -> 32046.188
C21: Total adjustments | D21: 124348 | E21: 402315 | F21: 243232 | G21: =SUM(G10:G20) -> 67474.168 | H21: =SUM(H10:H20) -> 156653.03 | I21: =SUM(I10:I20) -> 125703.51
C22: Net cash provided by operating activities | D22: 554506 | E22: 810690 | F22: 876357 | G22: =SUM(G8,G21) -> 630739.23 | H22: =SUM(H8,H21) -> 734077.71 | I22: =SUM(I8,I21) -> 745594.43
C24: Cash Flows from Investing Activities:
C25: Additions to property, plant and equipment | D25: -298611 | E25: -282304 | F25: -371015 | G25: =-FAM!H80 -> -347151.12 | H25: =-FAM!I80 -> -361983.52 | I25: =-FAM!J80 -> -377646.75
C26: Purchases of short-term investments | D26: 0 | E26: 0 | F26: -446309 | G26: ='Balance Sheet'!G10-'Balance Sheet'!H10 -> 196576.34 | H26: ='Balance Sheet'!H10-'Balance Sheet'!I10 -> -40838.666 | I26: ='Balance Sheet'!I10-'Balance Sheet'!J10 -> -56883.667
C27: Proceeds from the disposal of short-term investments | D27: 0 | E27: 0 | F27: 150274
C28: Investment in equity method investees | D28: -3094 | E28: -13741 | F28: -15720
C29: Proceeds from the sale of property, plant and equipment | D29: 7369 | E29: 695 | F29: 569
C30: Acquisition of distribution rights | D30: -30649 | E30: 0 | F30: 0
C31: Net cash used in investing activities | D31: -324985 | E31: -295350 | F31: -682201 | G31: =SUM(G25:G30) -> -150574.78 | H31: =SUM(H25:H30) -> -402822.18 | I31: =SUM(I25:I30) -> -434530.41
C33: Cash Flows from Financing Activities:
C34: Proceeds from bond issuance | D34: 0 | E34: 0 | F34: 1200000
C35: Payments related to share repurchases | D35: 0 | E35: 0 | F35: -625654
C36: Cash dividends paid | D36: -9374 | E36: -46868 | F36: -185635
C37: Payments of acquisition related contingent consideration | D37: -36515 | E37: -28208 | F37: -64312
C38: Debt issuance fees | D38: -310 | E38: -340 | F38: -15512 | G38: =DRS!H62 -> 68516.689 | H38: =DRS!I62 -> 19576.197 | I38: =DRS!J62 -> 0
C39: Payments on financing lease obligations | D39: -2988 | E39: -2303 | F39: -2488
C40: Payments on term loan facility and senior notes | D40: -125000 | E40: 0 | F40: 0 | G40: =DRS!H63 -> -350000 | H40: =DRS!I63 -> -100000 | I40: =DRS!J63 -> 0
C41: Net cash provided by (used in) financing activities | D41: -174187 | E41: -77719 | F41: 306399 | G41: =SUM(G34:G40) -> -281483.31 | H41: =SUM(H34:H40) -> -80423.803 | I41: =SUM(I34:I40) -> 0
C43: Net increase in cash | D43: 55334 | E43: 437621 | F43: 500555 | G43: =SUM(G22,G31,G41) -> 198681.13 | H43: =SUM(H22,H31,H41) -> 250831.72 | I43: =SUM(I22,I31,I41) -> 311064.01
C44: Cash at beginning of year | D44: 142314 | E44: 197648 | F44: 635269 | G44: =F45 -> 1135824 | H44: =G45 -> 1334505.1 | I44: =H45 -> 1585336.9
C45: Cash at end of year | D45: 197648 | E45: 635269 | F45: 1135824 | G45: =SUM(G43,G44) -> 1334505.1 | H45: =SUM(H43,H44) -> 1585336.9 | I45: =SUM(I43,I44) -> 1896400.9

Sheet FAM
B2: =Company_name -> Coca-Cola Consolidated, Inc. (COKE)
B3: Fixed Asset Model | E3: Historical | H3: Forcasted
B4: =currency -> in thousands, except per share data | D4: =EDATE(E4,-12) -> 44561 | E4: =EDATE(F4,-12) -> 44926 | F4: =EDATE(G4,-12) -> 45291 | G4: =LHY -> 45657 | H4: =EDATE(G4,12) -> 46022 | I4: =EDATE(H4,12) -> 46387 | J4: =EDATE(I4,12) -> 46752
C7: Land
C8: Opening | E8: =D11 -> 80261 | F8: =E11 -> 88185 | G8: =F11 -> 99858 | H8: =G11 -> 132543 | I8: =H11 -> 170443.44 | J8: =I11 -> 209963.22
C9: (+)Purchases | E9: =IF((E11-E8)>0,E11-E8,0) -> 7924 | F9: =IF((F11-F8)>0,F11-F8,0) -> 11673 | G9: =IF((G11-G8)>0,G11-G8,0) -> 32685 | H9: =H13*'Income Statement'!G$7 -> 37900.442 | I9: =I13*'Income Statement'!H$7 -> 39519.779 | J9: =J13*'Income Statement'!I$7 -> 41229.821
C10: (-)Sales | E10: =IF((E11-E8)<0,E11-E8,0) -> 0 | F10: =IF((F11-F8)<0,F11-F8,0) -> 0 | G10: =IF((G11-G8)<0,G11-G8,0) -> 0
C11: Closing | D11: 80261 | E11: 88185 | F11: 99858 | G11: 132543 | H11: =SUM(H8:H10) -> 170443.44 | I11: =SUM(I8:I10) -> 209963.22 | J11: =SUM(J8:J10) -> 251193.04
C13: Capex as % of Revenue | E13: =E9/'Income Statement'!$D$7 -> 0.0012778673 | F13: =F9/'Income Statement'!$D$7 -> 0.0018824514 | G13: =G9/'Income Statement'!$D$7 -> 0.0052709606 | H13: =G13 -> 0.0052709606 | I13: =H13 -> 0.0052709606 | J13: =I13 -> 0.0052709606
C15: Buildings
C16: Opening | E16: =D19 -> 265070 | F16: =E19 -> 352114 | G16: =F19 -> 390852 | H16: =G19 -> 493810 | I16: =H19 -> 613196.68 | J16: =I19 -> 737684.29
C17: (+)Purchases | E17: =IF((E19-E16)>0,E19-E16,0) -> 87044 | F17: =IF((F19-F16)>0,F19-F16,0) -> 38738 | G17: =IF((G19-G16)>0,G19-G16,0) -> 102958 | H17: =H21*'Income Statement'!G$7 -> 119386.68 | I17: =I21*'Income Statement'!H$7 -> 124487.6 | J17: =J21*'Income Statement'!I$7 -> 129874.25
C18: (-)Sales | E18: =IF((E19-E16)<0,E19-E16,0) -> 0 | F18: =IF((F19-F16)<0,F19-F16,0) -> 0 | G18: =IF((G19-G16)<0,G19-G16,0) -> 0
C19: Closing | D19: 265070 | E19: 352114 | F19: 390852 | G19: 493810 | H19: =SUM(H16:H18) -> 613196.68 | I19: =SUM(I16:I18) -> 737684.29 | J19: =SUM(J16:J18) -> 867558.54
C21: Capex as % of Revenue | E21: =E17/'Income Statement'!$D$7 -> 0.014037188 | F21: =F17/'Income Statement'!$D$7 -> 0.0062471002 | G21: =G17/'Income Statement'!$D$7 -> 0.016603566 | H21: =G21 -> 0.016603566 | I21: =H21 -> 0.016603566 | J21: =I21 -> 0.016603566
C23: Machinery and equipment
C24: Opening | E24: =D27 -> 443592 | F24: =E27 -> 462640 | G24: =F27 -> 498737 | H24: =G27 -> 563834 | I24: =H27 -> 639318.32 | J24: =I27 -> 718027.79
C25: (+)Purchases | E25: =IF((E27-E24)>0,E27-E24,0) -> 19048 | F25: =IF((F27-F24)>0,F27-F24,0) -> 36097 | G25: =IF((G27-G24)>0,G27-G24,0) -> 65097 | H25: =H29*'Income Statement'!G$7 -> 75484.322 | I25: =I29*'Income Statement'!H$7 -> 78709.47 | J25: =J29*'Income Statement'!I$7 -> 82115.273
C26: (-)Sales | E26: =IF((E27-E24)<0,E27-E24,0) -> 0 | F26: =IF((F27-F24)<0,F27-F24,0) -> 0 | G26: =IF((G27-G24)<0,G27-G24,0) -> 0
C27: Closing | D27: 443592 | E27: 462640 | F27: 498737 | G27: 563834 | H27: =SUM(H24:H26) -> 639318.32 | I27: =SUM(I24:I26) -> 718027.79 | J27: =SUM(J24:J26) -> 800143.06
C29: Capex as % of Revenue | E29: =E25/'Income Statement'!$D$7 -> 0.0030717839 | F29: =F25/'Income Statement'!$D$7 -> 0.0058211982 | G29: =G25/'Income Statement'!$D$7 -> 0.010497896 | H29: =G29 -> 0.010497896 | I29: =H29 -> 0.010497896 | J29: =I29 -> 0.010497896
C31: Transportation equipment
C32: Opening | E32: =D35 -> 466238 | F32: =E35 -> 515752 | G32: =F35 -> 611001 | H32: =G35 -> 682263 | I32: =H35 -> 764896.05 | J32: =I35 -> 851059.69
C33: (+)Purchases | E33: =IF((E35-E32)>0,E35-E32,0) -> 49514 | F33: =IF((F35-F32)>0,F35-F32,0) -> 95249 | G33: =IF((G35-G32)>0,G35-G32,0) -> 71262 | H33: =H37*'Income Statement'!G$7 -> 82633.052 | I33: =I37*'Income Statement'!H$7 -> 86163.637 | J33: =J37*'Income Statement'!I$7 -> 89891.985
C34: (-)Sales | E34: =IF((E35-E32)<0,E35-E32,0) -> 0 | F34: =IF((F35-F32)<0,F35-F32,0) -> 0 | G34: =IF((G35-G32)<0,G35-G32,0) -> 0
C35: Closing | D35: 466238 | E35: 515752 | F35: 611001 | G35: 682263 | H35: =SUM(H32:H34) -> 764896.05 | I35: =SUM(I32:I34) -> 851059.69 | J35: =SUM(J32:J34) -> 940951.67
C37: Capex as % of Revenue | E37: =E33/'Income Statement'!$D$7 -> 0.0079848965 | F37: =F33/'Income Statement'!$D$7 -> 0.015360371 | G37: =G33/'Income Statement'!$D$7 -> 0.011492097 | H37: =G37 -> 0.011492097 | I37: =H37 -> 0.011492097 | J37: =I37 -> 0.011492097
C39: Furniture and fixtures
C40: Opening | E40: =D43 -> 95062 | F40: =E43 -> 102099 | G40: =F43 -> 107072 | H40: =G43 -> 113156 | I40: =H43 -> 120210.8 | J40: =I43 -> 127567.03
C41: (+)Purchases | E41: =IF((E43-E40)>0,E43-E40,0) -> 7037 | F41: =IF((F43-F40)>0,F43-F40,0) -> 4973 | G41: =IF((G43-G40)>0,G43-G40,0) -> 6084 | H41: =H45*'Income Statement'!G$7 -> 7054.8046 | I41: =I45*'Income Statement'!H$7 -> 7356.2286 | J41: =J45*'Income Statement'!I$7 -> 7674.5367
C42: (-)Sales | E42: =IF((E43-E40)<0,E43-E40,0) -> 0 | F42: =IF((F43-F40)<0,F43-F40,0) -> 0 | G42: =IF((G43-G40)<0,G43-G40,0) -> 0
C43: Closing | D43: 95062 | E43: 102099 | F43: 107072 | G43: 113156 | H43: =SUM(H40:H42) -> 120210.8 | I43: =SUM(I40:I42) -> 127567.03 | J43: =SUM(J40:J42) -> 135241.57
C45: Capex as % of Revenue | E45: =E41/'Income Statement'!$D$7 -> 0.0011348248 | F45: =F41/'Income Statement'!$D$7 -> 0.00080197299 | G45: =G41/'Income Statement'!$D$7 -> 0.00098113888 | H45: =G45 -> 0.00098113888 | I45: =H45 -> 0.00098113888 | J45: =I45 -> 0.00098113888
C47: Cold drink dispensing equipment
C48: Opening | E48: =D51 -> 436954 | F48: =E51 -> 438879 | G48: =F51 -> 449508 | H48: =G51 -> 456984 | I48: =H51 -> 465652.92 | J48: =I51 -> 474692.23
C49: (+)Purchases | E49: =IF((E51-E48)>0,E51-E48,0) -> 1925 | F49: =IF((F51-F48)>0,F51-F48,0) -> 10629 | G49: =IF((G51-G48)>0,G51-G48,0) -> 7476 | H49: =H53*'Income Statement'!G$7 -> 8668.9217 | I49: =I53*'Income Statement'!H$7 -> 9039.3105 | J49: =J53*'Income Statement'!I$7 -> 9430.4465
C50: (-)Sales | E50: =IF((E51-E48)<0,E51-E48,0) -> 0 | F50: =IF((F51-F48)<0,F51-F48,0) -> 0 | G50: =IF((G51-G48)<0,G51-G48,0) -> 0
C51: Closing | D51: 436954 | E51: 438879 | F51: 449508 | G51: 456984 | H51: =SUM(H48:H50) -> 465652.92 | I51: =SUM(I48:I50) -> 474692.23 | J51: =SUM(J48:J50) -> 484122.68
C53: Capex as % of Revenue | E53: =E49/'Income Statement'!$D$7 -> 0.00031043595 | F53: =F49/'Income Statement'!$D$7 -> 0.0017140903 | G53: =G49/'Income Statement'!$D$7 -> 0.0012056204 | H53: =G53 -> 0.0012056204 | I53: =H53 -> 0.0012056204 | J53: =I53 -> 0.0012056204
C55: Leasehold and land improvements
...

Sheet Equity Shares
B2: =Company_name -> Coca-Cola Consolidated, Inc. (COKE)
B3: Equity Shares | E3: Historical | H3: Forcasted
B4: =currency -> in thousands, except per share data | D4: =EDATE(E4,-12) -> 44561 | E4: =EDATE(F4,-12) -> 44926 | F4: =EDATE(G4,-12) -> 45291 | G4: =LHY -> 45657 | H4: =EDATE(G4,12) -> 46022 | I4: =EDATE(H4,12) -> 46387 | J4: =EDATE(I4,12) -> 46752
C6: CommonStock
C7: Opening Balance | D7: 10204 | E7: 10204 | F7: 11431 | G7: 11431 | H7: =G15 -> 10833 | I7: =H15 -> 10833 | J7: =I15 -> 10833
C8: Net income | D8: 0 | E8: 0 | F8: 0 | G8: 0
C9: Other comprehensive income, net of tax | D9: 0 | E9: 0 | F9: 0 | G9: 0
C10: Dividends declared: | D10: 0
C11: Common Stock ($4.50per share) | D11: 0 | E11: 0 | F11: 0 | G11: 0
C12: Class B Common Stock ($4.50per share) | D12: 0 | E12: 0 | F12: 0 | G12: 0
C13: Conversion of1,227,546shares of Class B Common Stock | D13: 0 | E13: 1227
C14: Share repurchases(1) | D14: 0 | G14: -598
C15: Closing Balance | D15: 10204 | E15: 11431 | F15: 11431 | G15: 10833 | H15: =SUM(H7:H14) -> 10833 | I15: =SUM(I7:I14) -> 10833 | J15: =SUM(J7:J14) -> 10833
C17: Class BCommonStock
C18: Opening Balance | D18: 2860 | E18: 2860 | F18: 1633 | G18: 1633 | H18: =G26 -> 1633 | I18: =H26 -> 1633 | J18: =I26 -> 1633
C19: Net income | D19: 0 | E19: 0 | F19: 0 | G19: 0
C20: Other comprehensive income, net of tax | D20: 0 | E20: 0 | F20: 0 | G20: 0
C21: Dividends declared: | D21: 0
C22: Common Stock ($4.50per share) | D22: 0 | E22: 0 | F22: 0 | G22: 0
C23: Class B Common Stock ($4.50per share) | D23: 0 | E23: 0 | F23: 0 | G23: 0
C24: Conversion of1,227,546shares of Class B Common Stock | D24: 0 | E24: -1227
C25: Share repurchases(1) | D25: 0 | G25: 0
C26: Closing Balance | D26: 2860 | E26: 1633 | F26: 1633 | G26: 1633 | H26: =SUM(H18:H25) -> 1633 | I26: =SUM(I18:I25) -> 1633 | J26: =SUM(J18:J25) -> 1633
C28: Additional Paid-in Capital
C29: Opening Balance | D29: 135953 | E29: 135953 | F29: 135953 | G29: 135953 | H29: =G37 -> 135953 | I29: =H37 -> 135953 | J29: =I37 -> 135953
C30: Net income | D30: 0 | E30: 0 | F30: 0 | G30: 0
C31: Other comprehensive income, net of tax | D31: 0 | E31: 0 | F31: 0 | G31: 0
C32: Dividends declared: | D32: 0
C33: Common Stock ($4.50per share) | D33: 0 | E33: 0 | F33: 0 | G33: 0
C34: Class B Common Stock ($4.50per share) | D34: 0 | E34: 0 | F34: 0 | G34: 0
C35: Conversion of1,227,546shares of Class B Common Stock | D35: 0 | E35: 0
C36: Share repurchases(1) | D36: 0 | G36: 0
C37: Closing Balance | D37: 135953 | E37: 135953 | F37: 135953 | G37: 135953 | H37: =SUM(H29:H36) -> 135953 | I37: =SUM(I29:I36) -> 135953 | J37: =SUM(J29:J36) -> 135953
C39: RetainedEarnings
C40: Opening Balance | D40: 544280 | E40: 724486 | F40: 1112462 | G40: 1352111 | H40: =G48 -> 1395183 | I40: =H48 -> 1958448.1 | J40: =I48 -> 2535872.7
C41: Net income | D41: 189580 | E41: 430158 | F41: 408375 | G41: 633125 | H41: ='Income Statement'!G19 -> 563265.06 | I41: ='Income Statement'!H19 -> 577424.68 | J41: ='Income Statement'!I19 -> 619890.91
C42: Other comprehensive income, net of tax | D42: 0 | E42: 0 | F42: 0 | G42: 0
C43: Dividends declared: | D43: 0
C44: Common Stock ($4.50per share) | D44: -7141 | E44: -37354 | F44: -150642 | G44: -27452
C45: Class B Common Stock ($4.50per share) | D45: -2233 | E45: -4828 | F45: -18084 | G45: -3517
...

Sheet DRS
B2: =Company_name -> Coca-Cola Consolidated, Inc. (COKE)
B3: Deferred Revenue Schedule | E3: Historical | H3: Forcasted
B4: =currency -> in thousands, except per share data | D4: =EDATE(E4,-12) -> 44561 | E4: =EDATE(F4,-12) -> 44926 | F4: =EDATE(G4,-12) -> 45291 | G4: =LHY -> 45657 | H4: =EDATE(G4,12) -> 46022 | I4: =EDATE(H4,12) -> 46387 | J4: =EDATE(I4,12) -> 46752
B6: 2/27/2023 | C6: Senior notes(1)
C7: Opening | E7: =D10 -> 125000 | F7: =E10 -> 0 | G7: =F10 -> 0 | H7: =G10 -> 0 | I7: =H10 -> 0 | J7: =I10 -> 0
C8: (+)Issuance | E8: =IF((E10-E7)>0,E10-E7,0) -> 0 | F8: =IF((F10-F7)>0,F10-F7,0) -> 0 | G8: =IF((G10-G7)>0,G10-G7,0) -> 0
C9: (-)Repayment | E9: =IF((E10-E7)<0,E10-E7,0) -> -125000 | F9: =IF((F10-F7)<0,F10-F7,0) -> 0 | G9: =IF((G10-G7)<0,G10-G7,0) -> 0
C10: Closing | D10: 125000 | E10: 0 | F10: 0 | G10: 0 | H10: =SUM(H7:H9) -> 0 | I10: =SUM(I7:I9) -> 0 | J10: =SUM(J7:J9) -> 0
C11: Repayment Expense | D11: =D10*D12 -> 4100 | E11: =E10*E12 -> 0 | F11: =F10*F12 -> 0 | G11: =G10*G12 -> 0 | H11: =H10*H12 -> 0 | I11: =I10*I12 -> 0 | J11: =J10*J12 -> 0
C12: Interest Rate | D12: 0.0328 | E12: 0.0328 | F12: 0 | G12: 0 | H12: =G12 -> 0 | I12: =H12 -> 0 | J12: =I12 -> 0
B14: 11/25/2025 | C14: Senior bonds (the “2025 Senior Bonds”)
C15: Opening | E15: =D18 -> 350000 | F15: =E18 -> 350000 | G15: =F18 -> 350000 | H15: =G18 -> 350000 | I15: =H18 -> 0 | J15: =I18 -> 0
C16: (+)Issuance | E16: =IF((E18-E15)>0,E18-E15,0) -> 0 | F16: =IF((F18-F15)>0,F18-F15,0) -> 0 | G16: =IF((G18-G15)>0,G18-G15,0) -> 0
C17: (-)Repayment | E17: =IF((E18-E15)<0,E18-E15,0) -> 0 | F17: =IF((F18-F15)<0,F18-F15,0) -> 0 | G17: =IF((G18-G15)<0,G18-G15,0) -> 0 | H17: =-H15 -> -350000
C18: Closing | D18: 350000 | E18: 350000 | F18: 350000 | G18: 350000 | H18: =SUM(H15:H17) -> 0 | I18: =SUM(I15:I17) -> 0 | J18: =SUM(J15:J17) -> 0
C19: Repayment Expense | D19: =D18*D20 -> 13300 | E19: =E18*E20 -> 13300 | F19: =F18*F20 -> 13300 | G19: =G18*G20 -> 13300 | H19: =H18*H20 -> 0 | I19: =I18*I20 -> 0 | J19: =J18*J20 -> 0
C20: Interest Rate | D20: 0.038 | E20: 0.038 | F20: 0.038 | G20: 0.038 | H20: =G20 -> 0.038 | I20: =H20 -> 0.038 | J20: =I20 -> 0.038
B22: 46305 | C22: Senior notes
C23: Opening | E23: =D26 -> 100000 | F23: =E26 -> 100000 | G23: =F26 -> 100000 | H23: =G26 -> 100000 | I23: =H26 -> 100000 | J23: =I26 -> 0
C24: (+)Issuance | E24: =IF((E26-E23)>0,E26-E23,0) -> 0 | F24: =IF((F26-F23)>0,F26-F23,0) -> 0 | G24: =IF((G26-G23)>0,G26-G23,0) -> 0
C25: (-)Repayment | E25: =IF((E26-E23)<0,E26-E23,0) -> 0 | F25: =IF((F26-F23)<0,F26-F23,0) -> 0 | G25: =IF((G26-G23)<0,G26-G23,0) -> 0 | I25: =-I23 -> -100000
C26: Closing | D26: 100000 | E26: 100000 | F26: 100000 | G26: 100000 | H26: =SUM(H23:H25) -> 100000 | I26: =SUM(I23:I25) -> 0 | J26: =SUM(J23:J25) -> 0
C27: Repayment Expense | D27: =D26*D28 -> 3930 | E27: =E26*E28 -> 3930 | F27: =F26*F28 -> 3930 | G27: =G26*G28 -> 3930 | H27: =H26*H28 -> 3930 | I27: =I26*I28 -> 0 | J27: =J26*J28 -> 0
C28: Interest Rate | D28: 0.0393 | E28: 0.0393 | F28: 0.0393 | G28: 0.0393 | H28: =G28 -> 0.0393 | I28: =H28 -> 0.0393 | J28: =I28 -> 0.0393
B30: 47124 | C30: Senior bonds (the “2029 Senior Bonds”)
C31: Opening | E31: =D34 -> 0 | F31: =E34 -> 0 | G31: =F34 -> 0 | H31: =G34 -> 700000 | I31: =H34 -> 700000 | J31: =I34 -> 700000
C32: (+)Issuance | E32: =IF((E34-E31)>0,E34-E31,0) -> 0 | F32: =IF((F34-F31)>0,F34-F31,0) -> 0 | G32: =IF((G34-G31)>0,G34-G31,0) -> 700000
C33: (-)Repayment | E33: =IF((E34-E31)<0,E34-E31,0) -> 0 | F33: =IF((F34-F31)<0,F34-F31,0) -> 0 | G33: =IF((G34-G31)<0,G34-G31,0) -> 0
C34: Closing | D34: 0 | E34: 0 | F34: 0 | G34: 700000 | H34: =SUM(H31:H33) -> 700000 | I34: =SUM(I31:I33) -> 700000 | J34: =SUM(J31:J33) -> 700000
C35: Repayment Expense | D35: =D34*D36 -> 0 | E35: =E34*E36 -> 0 | F35: =F34*F36 -> 0 | G35: =G34*G36 -> 36750 | H35: =H34*H36 -> 36750 | I35: =I34*I36 -> 36750 | J35: =J34*J36 -> 36750
C36: Interest Rate | D36: 0 | E36: 0 | F36: 0.0525 | G36: 0.0525 | H36: =G36 -> 0.0525 | I36: =H36 -> 0.0525 | J36: =I36 -> 0.0525
B38: 3/21/2030 | C38: Senior notes
C39: Opening | E39: =D42 -> 150000 | F39: =E42 -> 150000 | G39: =F42 -> 150000 | H39: =G42 -> 150000 | I39: =H42 -> 150000 | J39: =I42 -> 150000
C40: (+)Issuance | E40: =IF((E42-E39)>0,E42-E39,0) -> 0 | F40: =IF((F42-F39)>0,F42-F39,0) -> 0 | G40: =IF((G42-G39)>0,G42-G39,0) -> 0
C41: (-)Repayment | E41: =IF((E42-E39)<0,E42-E39,0) -> 0 | F41: =IF((F42-F39)<0,F42-F39,0) -> 0 | G41: =IF((G42-G39)<0,G42-G39,0) -> 0
C42: Closing | D42: 150000 | E42: 150000 | F42: 150000 | G42: 150000 | H42: =SUM(H39:H41) -> 150000 | I42: =SUM(I39:I41) -> 150000 | J42: =SUM(J39:J41) -> 150000
C43: Repayment Expense | D43: =D42*D44 -> 5940 | E43: =E42*E44 -> 5940 | F43: =F42*F44 -> 5940 | G43: =G42*G44 -> 5940 | H43: =H42*H44 -> 5940 | I43: =I42*I44 -> 5940 | J43: =J42*J44 -> 5940
C44: Interest Rate | D44: 0.0396 | E44: 0.0396 | F44: 0.0396 | G44: 0.0396 | H44: =G44 -> 0.0396 | I44: =H44 -> 0.0396 | J44: =I44 -> 0.0396
B46: 48950 | C46: Senior bonds (the “2034 Senior Bonds”)
C47: Opening | E47: =D50 -> 0 | F47: =E50 -> 0 | G47: =F50 -> 0 | H47: =G50 -> 500000 | I47: =H50 -> 500000 | J47: =I50 -> 500000
...

Sheet Revenue Driver
B2: =Company_name -> Coca-Cola Consolidated, Inc. (COKE)
B3: Revenue Driver | G3: Historical | J3: Forcasted
B4: =currency -> in thousands, except per share data | D4: =EDATE(E4,-12) -> 43830 | E4: =EDATE(F4,-12) -> 44196 | F4: =EDATE(G4,-12) -> 44561 | G4: =EDATE(H4,-12) -> 44926 | H4: =EDATE(I4,-12) -> 45291 | I4: =LHY -> 45657 | J4: =EDATE(I4,12) -> 46022 | K4: =EDATE(J4,12) -> 46387 | L4: =EDATE(K4,12) -> 46752
C7: Bottle/can sales:
C8: Sparkling beverages | D8: 2582478 | E8: 2760827 | F8: 3020887 | G8: 3521273 | H8: 3892133 | I8: 4106073 | J8: 4331772.7 | K8: 4569878.5 | L8: =L11*L13 -> 4821072.3
C9: As % of Net Sales | D9: =D8/D$33 -> 0.53505683 | E9: =E8/E$33 -> 0.55135414 | F9: =F8/F$33 -> 0.54305992 | G9: =G8/G$33 -> 0.56785961 | H9: =H8/H$33 -> 0.5849438 | I9: =I8/I$33 -> 0.59510754 | J9: =J8/J$33 -> 0.60243633 | K9: =K8/K$33 -> 0.60950872 | L9: =L8/L$33 -> 0.61634228
C10: YoY growth | E10: =E8/D8-1 -> 0.069061189 | F10: =F8/E8-1 -> 0.094196413 | G10: =G8/F8-1 -> 0.16564208 | H10: =H8/G8-1 -> 0.10531987 | I10: =I8/H8-1 -> 0.054967289 | J10: =I10 -> 0.054967289 | K10: =J10 -> 0.054967289 | L10: =K10 -> 0.054967289
C11: Volume | F11: 254028 | G11: 255514 | H11: 263872 | I11: 266686 | J11: =I11*(1+J12) -> 269530.01 | K11: =J11*(1+K12) -> 272404.35 | L11: =K11*(1+L12) -> 275309.34
C12: YoY growth | G12: =G11/F11-1 -> 0.0058497488 | H12: =H11/G11-1 -> 0.032710536 | I12: =I11/H11-1 -> 0.010664261 | J12: =I12 -> 0.010664261 | K12: =J12 -> 0.010664261 | L12: =K12 -> 0.010664261
C13: Price Per Product | F13: =F8/F11 -> 11.891945 | G13: =G8/G11 -> 13.781135 | H13: =H8/H11 -> 14.75008 | I13: =I8/I11 -> 15.396657 | J13: =I13*(1+J14) -> 16.071579 | K13: =J13*(1+K14) -> 16.776085 | L13: =K13*(1+L14) -> 17.511474
C14: YoY growth | G14: =G13/F13-1 -> 0.15886302 | H14: =H13/G13-1 -> 0.070309469 | I14: =I13/H13-1 -> 0.043835554 | J14: =I14 -> 0.043835554 | K14: =J14 -> 0.043835554 | L14: =K14 -> 0.043835554
C15: Still beverages | D15: 1558944 | E15: 1641716 | F15: 1861162 | G15: 2020100 | H15: 2149639 | I15: 2227243 | J15: 2307648.6 | K15: 2390956.9 | L15: =L18*L20 -> 2477272.7
C16: As % of Net Sales | D16: =D15/D$33 -> 0.32299351 | E16: =E15/E$33 -> 0.32786079 | F16: =F15/F$33 -> 0.33457805 | G16: =G15/G$33 -> 0.3257723 | H16: =H15/H$33 -> 0.32306656 | I16: =I15/I$33 -> 0.32280213 | J16: =J15/J$33 -> 0.32093358 | K16: =K15/K$33 -> 0.31889449 | L16: =L15/L$33 -> 0.31670296
C17: YoY growth | E17: =E15/D15-1 -> 0.053094916 | F17: =F15/E15-1 -> 0.13366867 | G17: =G15/F15-1 -> 0.085397187 | H17: =H15/G15-1 -> 0.064125043 | I17: =I15/H15-1 -> 0.036100945 | J17: =I17 -> 0.036100945 | K17: =J17 -> 0.036100945 | L17: =K17 -> 0.036100945
C18: Volume | F18: 112008 | G18: 110601 | H18: 91495 | I18: 86417 | J18: =I18*(1+J19) -> 81620.831 | K18: =J18*(1+K19) -> 77090.85 | L18: =K18*(1+L19) -> 72812.285
C19: YoY growth | G19: =G18/F18-1 -> -0.012561603 | H19: =H18/G18-1 -> -0.17274708 | I19: =I18/H18-1 -> -0.055500301 | J19: =I19 -> -0.055500301 | K19: =J19 -> -0.055500301 | L19: =K19 -> -0.055500301
C20: Price Per Product | F20: =F15/F18 -> 16.616331 | G20: =G15/G18 -> 18.264753 | H20: =H15/H18 -> 23.494606 | I20: =I15/I18 -> 25.773204 | J20: =I20*(1+J21) -> 28.27279 | K20: =J20*(1+K21) -> 31.014795 | L20: =K20*(1+L21) -> 34.02273
C21: YoY growth | G21: =G20/F20-1 -> 0.099204963 | H21: =H20/G20-1 -> 0.2863358 | I21: =I20/H20-1 -> 0.09698388 | J21: =I21 -> 0.09698388 | K21: =J21 -> 0.09698388 | L21: =K21 -> 0.09698388
C22: Total bottle/can sales | D22: 4141422 | E22: 4402543 | F22: 4882049 | G22: 5541373 | H22: 6041772 | I22: 6333316 | J22: =SUM(J8,J15) -> 6639421.3 | K22: =SUM(K8,K15) -> 6960835.4 | L22: =SUM(L8,L15) -> 7298345
C24: Other sales:
C25: Sales to other Coca‑Cola bottlers | D25: 342062 | E25: 329574 | F25: 347185 | G25: 349837 | H25: 353819 | I25: 345586 | J25: 346462.39 | K25: 347340.99 | L25: =K25*(1+L27) -> 348221.83
C26: As % of Net Sales | D26: =D25/D$33 -> 0.070870927 | E26: =E25/E$33 -> 0.065817955 | F26: =F25/F$33 -> 0.06241288 | G26: =G25/G$33 -> 0.056416614 | H26: =H25/H$33 -> 0.053175015 | I26: =I25/I$33 -> 0.050086989 | J26: =J25/J$33 -> 0.04818386 | K26: =K25/K$33 -> 0.046326694 | L26: =L25/L$33 -> 0.044517863
C27: YoY growth | E27: =E25/D25-1 -> -0.036508001 | F27: =F25/E25-1 -> 0.053435647 | G27: =G25/F25-1 -> 0.0076385789 | H27: =H25/G25-1 -> 0.011382444 | I27: =I25/H25-1 -> -0.02326896 | J27: =AVERAGE($E$27:$I$27) -> 0.0025359418 | K27: =AVERAGE($E$27:$I$27) -> 0.0025359418 | L27: =AVERAGE($E$27:$I$27) -> 0.0025359418
C28: Post-mix sales and other | D28: 343065 | E28: 275240 | F28: 333480 | G28: 309747 | H28: 258267 | I28: 220814 | J28: 204540.43 | K28: 189466.2 | L28: =K28*(1+L30) -> 175502.91
C29: As % of Net Sales | D29: =D28/D$33 -> 0.071078736 | E29: =E28/E$33 -> 0.054967121 | F29: =F28/F$33 -> 0.059949154 | G29: =G28/G$33 -> 0.049951483 | H29: =H28/H$33 -> 0.038814625 | I29: =I28/I$33 -> 0.032003346 | J29: =J28/J$33 -> 0.028446227 | K29: =K28/K$33 -> 0.025270103 | L29: =L28/L$33 -> 0.022436888
C30: YoY growth | E30: =E28/D28-1 -> -0.19770306 | F30: =F28/E28-1 -> 0.21159715 | G30: =G28/F28-1 -> -0.071167686 | H30: =H28/G28-1 -> -0.16620016 | I30: =I28/H28-1 -> -0.14501659 | J30: =AVERAGE($E$30:$I$30) -> -0.073698068 | K30: =AVERAGE($E$30:$I$30) -> -0.073698068 | L30: =AVERAGE($E$30:$I$30) -> -0.073698068
C31: Total other sales | D31: 685127 | E31: 604814 | F31: 680665 | G31: 659584 | H31: 612086 | I31: 566400 | J31: =SUM(J25,J28) -> 551002.82 | K31: =SUM(K25,K28) -> 536807.19 | L31: =SUM(L25,L28) -> 523724.74
C33: Total net sales | D33: 4826549 | E33: 5007357 | F33: 5562714 | G33: 6200957 | H33: 6653858 | I33: 6899716 | J33: =SUM(J22,J31) -> 7190424.1 | K33: =SUM(K22,K31) -> 7497642.6 | L33: =SUM(L22,L31) -> 7822069.8
C34: YoY Growth of Total Net Sales | E34: =E33/D33-1 -> 0.037461134 | F34: =F33/E33-1 -> 0.11090821 | G34: =G33/F33-1 -> 0.1147359 | H34: =H33/G33-1 -> 0.073037275 | I34: =I33/H33-1 -> 0.036949691 | J34: =J33/I33-1 -> 0.042133343 | K34: =K33/J33-1 -> 0.042726057 | L34: =L33/K33-1 -> 0.043270558

Sheet Sheet1
D5: =EDATE(E5,-12) -> 45291 | E5: =LHY -> 45657 | F5: =EDATE(E5,12) -> 46022 | G5: =EDATE(F5,12) -> 46387
C6: Sparkling beverages | D6: 3892133 | E6: 4106073 | F6: 4331772.7 | G6: 4569878.5
C7: Still beverages | D7: 2149639 | E7: 2227243 | F7: 2307648.6 | G7: 2390956.9
C8: Sales to other Coca‑Cola bottlers | D8: 353819 | E8: 345586 | F8: 346462.39 | G8: 347340.99
C9: Post-mix sales and other | D9: 258267 | E9: 220814 | F9: 204540.43 | G9: 189466.2

Sheet BETA
C3: Coca-Cola INC(COKE) | G3: S&P 500
C4: Date | D4: Adj Close | E4: % Return | G4: Date | H4: Adj Close | I4: %Return
C5: Sep 1, 2025 | D5: 117.19 | E5: =D5/D6-1 -> -0.00042647561 | G5: Sep 1, 2025 | H5: 6448.26 | I5: =H5/H6-1 -> -0.0018575104 | L5: Beta (Slope) | M5: =SLOPE(E5:E63,I5:I63) -> 0.67005995
C6: Aug 1, 2025 | D6: 117.24 | E6: =D6/D7-1 -> 0.051479821 | G6: Aug 1, 2025 | H6: 6460.26 | I6: =H6/H7-1 -> 0.019066503
C7: Jul 1, 2025 | D7: 111.5 | E7: =D7/D8-1 -> 0.00089766607 | G7: Jul 1, 2025 | H7: 6339.39 | I7: =H7/H8-1 -> 0.021666573 | L7: Beta (Covar) | M7: =_xlfn.COVARIANCE.P(E5:E63,I5:I63)/_xlfn.VAR.P(I5:I63) -> 0.67005995
C8: Jun 1, 2025 | D8: 111.4 | E8: =D8/D9-1 -> -0.026138648 | G8: Jun 1, 2025 | H8: 6204.95 | I8: =H8/H9-1 -> 0.049606796
C9: May 1, 2025 | D9: 114.39 | E9: =D9/D10-1 -> -0.15285492 | G9: May 1, 2025 | H9: 5911.69 | I9: =H9/H10-1 -> 0.061523848 | L9: CAGR | M9: =(H5/H64)^(1/4)-1 -> 0.18501821
C10: Apr 1, 2025 | D10: 135.03 | E10: =D10/D11-1 -> 0.0042391789 | G10: Apr 1, 2025 | H10: 5569.06 | I10: =H10/H11-1 -> -0.0076249365
C11: Mar 1, 2025 | D11: 134.46 | E11: =D11/D12-1 -> -0.047328893 | G11: Mar 1, 2025 | H11: 5611.85 | I11: =H11/H12-1 -> -0.057544714
C12: Feb 1, 2025 | D12: 141.14 | E12: =D12/D13-1 -> 0.056199955 | G12: Feb 1, 2025 | H12: 5954.5 | I12: =H12/H13-1 -> -0.014242128
C13: Jan 1, 2025 | D13: 133.63 | E13: =D13/D14-1 -> 0.085452035 | G13: Jan 1, 2025 | H13: 6040.53 | I13: =H13/H14-1 -> 0.02701632
C14: Dec 1, 2024 | D14: 123.11 | E14: =D14/D15-1 -> -0.033976773 | G14: Dec 1, 2024 | H14: 5881.63 | I14: =H14/H15-1 -> -0.024990137
C15: Nov 1, 2024 | D15: 127.44 | E15: =D15/D16-1 -> 0.16245553 | G15: Nov 1, 2024 | H15: 6032.38 | I15: =H15/H16-1 -> 0.057301352
C16: Oct 1, 2024 | D16: 109.63 | E16: =D16/D17-1 -> -0.14598426 | G16: Oct 1, 2024 | H16: 5705.45 | I16: =H16/H17-1 -> -0.0098967806
C17: Sep 1, 2024 | D17: 128.37 | E17: =D17/D18-1 -> -0.019327731 | G17: Sep 1, 2024 | H17: 5762.48 | I17: =H17/H18-1 -> 0.02019687
C18: Aug 1, 2024 | D18: 130.9 | E18: =D18/D19-1 -> 0.17199391 | G18: Aug 1, 2024 | H18: 5648.4 | I18: =H18/H19-1 -> 0.022834688
C19: Jul 1, 2024 | D19: 111.69 | E19: =D19/D20-1 -> 0.056170213 | G19: Jul 1, 2024 | H19: 5522.3 | I19: =H19/H20-1 -> 0.011321349
C20: Jun 1, 2024 | D20: 105.75 | E20: =D20/D21-1 -> 0.10594018 | G20: Jun 1, 2024 | H20: 5460.48 | I20: =H20/H21-1 -> 0.034669759
C21: May 1, 2024 | D21: 95.62 | E21: =D21/D22-1 -> 0.19480195 | G21: May 1, 2024 | H21: 5277.51 | I21: =H21/H22-1 -> 0.048021224
... C63: Nov 1, 2020 | D63: 22.71 | E63: =D63/D64-1 -> 0.1440806 | G63: Nov 1, 2020 | H63: 3621.63 | I63: =H63/H64-1 -> 0.10754566
C64: Oct 1, 2020 | D64: 19.85 | G64: Oct 1, 2020 | H64: 3269.96

Sheet Working Capital
B2: =Company_name -> Coca-Cola Consolidated, Inc. (COKE)
B3: Working Capital | E3: Historical | H3: Forcasted
B4: =currency -> in thousands, except per share data | D4: =EDATE(E4,-12) -> 44561 | E4: =EDATE(F4,-12) -> 44926 | F4: =EDATE(G4,-12) -> 45291 | G4: =LHY -> 45657 | H4: =EDATE(G4,12) -> 46022 | I4: =EDATE(H4,12) -> 46387 | J4: =EDATE(I4,12) -> 46752
C6: Current Assets:
C7: Short-term investments | D7: 0 | E7: 0 | F7: 0 | G7: 301210 | H7: =G7*(1+3%) -> 310246.3 | I7: =H7*(1+3%) -> 319553.69 | J7: =I7*(1+3%) -> 329140.3
C8: Accounts receivable, trade | D8: 472270 | E8: 532047 | F8: 555933 | G8: 567653 | H8: =G8*(1+3%) -> 584682.59 | I8: =H8*(1+3%) -> 602223.07 | J8: =I8*(1+3%) -> 620289.76
C9: Allowance for doubtful accounts | D9: -17336 | E9: -16119 | F9: -16060 | G9: -14674 | H9: =G9*(1+3%) -> -15114.22 | I9: =H9*(1+3%) -> -15567.647 | J9: =I9*(1+3%) -> -16034.676
C10: Accounts receivable from The Coca-Cola Company | D10: 57737 | E10: 35786 | F10: 51936 | G10: 89871 | H10: =G10*(1+3%) -> 92567.13 | I10: =H10*(1+3%) -> 95344.144 | J10: =I10*(1+3%) -> 98204.468
C11: Accounts receivable, other | D11: 33878 | E11: 54631 | F11: 67533 | G11: 40692 | H11: =G11*(1+3%) -> 41912.76 | I11: =H11*(1+3%) -> 43170.143 | J11: =I11*(1+3%) -> 44465.247
C12: Inventories | D12: 302851 | E12: 347545 | F12: 321932 | G12: 330395 | H12: =G12*(1+3%) -> 340306.85 | I12: =H12*(1+3%) -> 350516.06 | J12: =I12*(1+3%) -> 361031.54
C13: Prepaid expenses and other current assets | D13: 78068 | E13: 94263 | F13: 88585 | G13: 96331 | H13: =G13*(1+3%) -> 99220.93 | I13: =H13*(1+3%) -> 102197.56 | J13: =I13*(1+3%) -> 105263.48
C14: Assets held for sale | D14: 6880 | E14: 0 | F14: 0 | G14: 0 | H14: =G14*(1+3%) -> 0 | I14: =H14*(1+3%) -> 0 | J14: =I14*(1+3%) -> 0
C15: Total current assets | D15: =SUM(D7:D14) -> 934348 | E15: =SUM(E7:E14) -> 1048153 | F15: =SUM(F7:F14) -> 1069859 | G15: =SUM(G7:G14) -> 1411478 | H15: =SUM(H7:H14) -> 1453822.3 | I15: =SUM(I7:I14) -> 1497437 | J15: =SUM(J7:J14) -> 1542360.1
C16: ∆Current Assets | E16: =D15-E15 -> -113805 | F16: =E15-F15 -> -21706 | G16: =F15-G15 -> -341619 | H16: =G15-H15 -> -42344.34 | I16: =H15-I15 -> -43614.67 | J16: =I15-J15 -> -44923.11
C18: Current Liabilities:
C19: Accounts payable, trade | D19: 319318 | E19: 351729 | F19: 383562 | G19: 334878 | H19: =G19*(1+3%) -> 344924.34 | I19: =H19*(1+3%) -> 355272.07 | J19: =I19*(1+3%) -> 365930.23
C20: Accounts payable to The Coca-Cola Company | D20: 145671 | E20: 162783 | F20: 139499 | G20: 187271 | H20: =G20*(1+3%) -> 192889.13 | I20: =H20*(1+3%) -> 198675.8 | J20: =I20*(1+3%) -> 204636.08
C21: Other accrued liabilities | D21: 226769 | E21: 198300 | F21: 237994 | G21: 246687 | H21: =G21*(1+3%) -> 254087.61 | I21: =H21*(1+3%) -> 261710.24 | J21: =I21*(1+3%) -> 269561.55
C22: Accrued compensation | D22: 110894 | E22: 126921 | F22: 146932 | G22: 168692 | H22: =G22*(1+3%) -> 173752.76 | I22: =H22*(1+3%) -> 178965.34 | J22: =I22*(1+3%) -> 184334.3
C23: Accrued interest payable | D23: 4096 | E23: 2677 | F23: 0 | G23: 0 | H23: =G23*(1+3%) -> 0 | I23: =H23*(1+3%) -> 0 | J23: =I23*(1+3%) -> 0
C24: Dividends payable | D24: 0 | E24: 32808 | F24: 154666 | G24: 0 | H24: =G24*(1+3%) -> 0 | I24: =H24*(1+3%) -> 0 | J24: =I24*(1+3%) -> 0
C25: Total current liabilities | D25: =SUM(D19:D24) -> 806748 | E25: =SUM(E19:E24) -> 875218 | F25: =SUM(F19:F24) -> 1062653 | G25: =SUM(G19:G24) -> 937528 | H25: =SUM(H19:H24) -> 965653.84 | I25: =SUM(I19:I24) -> 994623.46 | J25: =SUM(J19:J24) -> 1024462.2
C26: ∆Current Liabilities | E26: =E25-D25 -> 68470 | F26: =F25-E25 -> 187435 | G26: =G25-F25 -> -125125 | H26: =H25-G25 -> 28125.84 | I26: =I25-H25 -> 28969.615 | J26: =J25-I25 -> 29838.704
C28: Net Working Capital | D28: =D15-D25 -> 127600 | E28: =E15-E25 -> 172935 | F28: =F15-F25 -> 7206 | G28: =G15-G25 -> 473950 | H28: =H15-H25 -> 488168.5 | I28: =I15-I25 -> 502813.55 | J28: =J15-J25 -> 517897.96
C30: ∆Working Capital | E30: =E28-D28 -> 45335 | F30: =F28-E28 -> -165729 | G30: =G28-F28 -> 466744 | H30: =H28-G28 -> 14218.5 | I30: =I28-H28 -> 14645.055 | J30: =J28-I28 -> 15084.407

Sheet WACC
B2: =Company_name -> Coca-Cola Consolidated, Inc. (COKE)
B3: Weighted Average Cost of Capital
B4: =currency -> in thousands, except per share data
B6: S.NO. | C6: Company Name | D6: Ticker | E6: Country | F6: Total Debt | G6: Total Equity | H6: Tax Rate | I6: Debt/Equity | J6: Debt/Capital | K6: Levered Beta | L6: Unlevered Beta
B7: 1 | C7: Coca-Cola | D7: COKE | E7: US | F7: ='Balance Sheet'!G30+'Balance Sheet'!G31+'Balance Sheet'!G38+'Balance Sheet'!G43+'Balance Sheet'!G44+'Balance Sheet'!G45 -> 1906998 | G7: ='Balance Sheet'!G60 -> 1417611 | H7: 0.21 | I7: =F7/G7 -> 1.3452195 | J7: =F7/(F7+G7) -> 0.57360069 | K7: =BETA!M5 -> 0.67005995 | L7: =K7/(1+I7)*(1-H7) -> 0.22571335
B8: 2 | C8: P&G | D8: PG | E8: US | F8: 34508 | G8: 52284 | H8: 0.21 | I8: =F8/G8 -> 0.66001071 | J8: =F8/(F8+G8) -> 0.39759425 | K8: 0.37 | L8: =K8/(1+I8)*(1-H8) -> 0.1760832
B9: 3 | C9: PepsiCo | D9: PEP | E9: US | F9: 44306 | G9: 18171 | H9: 0.21 | I9: =F9/G9 -> 2.4382808 | J9: =F9/(F9+G9) -> 0.70915697 | K9: 0.46 | L9: =K9/(1+I9)*(1-H9) -> 0.10569236
B10: 4 | C10: Philip Morris International | D10: PM | E10: US | F10: 45558 | G10: -9870 | H10: 0.21 | I10: =F10/G10 -> -4.6158055 | J10: =F10/(F10+G10) -> 1.2765636 | K10: 0.51 | L10: =K10/(1+I10)*(1-H10) -> -0.11142745
B11: 5 | C11: Altria | D11: MO | E11: US | F11: 24926 | G11: -2188 | H11: 0.21 | I11: =F11/G11 -> -11.392139 | J11: =F11/(F11+G11) -> 1.0962266 | K11: 0.62 | L11: =K11/(1+I11)*(1-H11) -> -0.047131779
C12: Mean(Average) | F12: =AVERAGE(F7:F11) -> 411259.2 | G12: =AVERAGE(G7:G11) -> 295201.6 | I12: =AVERAGE(I7:I11) -> -2.3128867 | J12: =AVERAGE(J7:J11) -> 0.81062841 | K12: =AVERAGE(K7:K11) -> 0.52601199 | L12: =AVERAGE(L7:L11) -> 0.069785936
C13: Median | F13: =MEDIAN(F7:F11) -> 44306 | G13: =MEDIAN(G7:G11) -> 18171 | I13: =MEDIAN(I7:I11) -> 0.66001071 | J13: =MEDIAN(J7:J11) -> 0.70915697 | K13: =MEDIAN(K7:K11) -> 0.51 | L13: =MEDIAN(L7:L11) -> 0.10569236
C16: Cost of Debt | H16: Cost of Equity | K16: Cost of Prefernce
C17: Cost of Pre-Tax Debt | D17: ='Income Statement'!D12/WACC!F7 -> 0.013000538 | H17: Risk Free Rate of Return | I17: 0.0429 | K17: Cost of Prefernce Share | L17: 0
C18: Less - Tax Rate | D18: =H7 -> 0.21 | H18: Levered Beta | I18: =K7 -> 0.67005995
C19: Post Tax Cost of Debt | D19: =D17*(1-D18) -> 0.010270425 | H19: Market Rate of Return | I19: =BETA!M9 -> 0.18501821
H20: Cost of Equity | I20: =I17+I18*(I19-I17) -> 0.13812772
H21: Weight of Equity | I21: =G7/(F7+G7) -> 0.42639931
C23: Capital Structure | E23: Weight | F23: Target | H23: WACC Calculation
C24: Debt | D24: =F7 -> 1906998 | E24: =D24/D27 -> 0.57360069 | F24: =J12 -> 0.81062841 | H24: Cost of Debt | I24: =D19 -> 0.010270425
C25: Equity | D25: =G7 -> 1417611 | E25: =D25/D27 -> 0.42639931 | F25: =1-F24 -> 0.18937159 | H25: Weight of Debt | I25: =F24 -> 0.81062841
C26: Prefernce Share | D26: 0 | E26: 0 | F26: 0
C27: Total | D27: =SUM(D24:D26) -> 3324609 | E27: =SUM(E24:E26) -> 1 | F27: =SUM(F24:F26) -> 1 | H27: Cost of Equity | I27: =I20 -> 0.13812772
H28: Weight of Equity | I28: =F25 -> 0.18937159
H30: Cost of Preference | I30: 0
H31: Weight of Prefernce | I31: 0
H33: WACC CALCULATION | I33: =I24*I25+I27*I28+I30*I31 -> 0.034482965

Sheet Ratios
B2: =Company_name -> Coca-Cola Consolidated, Inc. (COKE)
B3: Ratios | D3: Historical | G3: Forcasted | J3: Performace Managemet
B4: =currency -> in thousands, except per share data | D4: =EDATE(E4,-12) -> 44926 | E4: =EDATE(F4,-12) -> 45291 | F4: =LHY -> 45657 | G4: =EDATE(F4,12) -> 46022 | H4: =EDATE(G4,12) -> 46387 | I4: =EDATE(H4,12) -> 46752 | J4: Trend Line | K4: Industry | L4: Vs Industry
B6: Growth % Ratios:
C7: YoY Revenue Growth % | E7: 0.073037275 | F7: 0.036949691 | G7: 0.042133343 | H7: 0.042726057 | I7: ='Income Statement'!I7/'Income Statement'!H7-1 -> 0.043270558
C8: YoY Operating Profit Growth % | E8: ='Income Statement'!E11/'Income Statement'!D11-1 -> 0.30170019 | F8: ='Income Statement'!F11/'Income Statement'!E11-1 -> 0.10294074 | G8: ='Income Statement'!G11/'Income Statement'!F11-1 -> -0.056806191 | H8: ='Income Statement'!H11/'Income Statement'!G11-1 -> 0.042726057 | I8: ='Income Statement'!I11/'Income Statement'!H11-1 -> 0.043270558
C9: YoY Net Profit Growth % | E9: ='Income Statement'!E19/'Income Statement'!D19-1 -> -0.050639532 | F9: ='Income Statement'!F19/'Income Statement'!E19-1 -> 0.550352 | G9: ='Income Statement'!G19/'Income Statement'!F19-1 -> -0.11034147 | H9: ='Income Statement'!H19/'Income Statement'!G19-1 -> 0.025138473 | I9: ='Income Statement'!I19/'Income Statement'!H19-1 -> 0.073544193
B11: Profitability Ratios:
C12: Gross Profit Margin | D12: ='Income Statement'!D9/'Income Statement'!D7 -> 0.36735523 | E12: ='Income Statement'!E9/'Income Statement'!E7 -> 0.39055703 | F12: ='Income Statement'!F9/'Income Statement'!F7 -> 0.39902787 | G12: ='Income Statement'!G9/'Income Statement'!G7 -> 0.38564671 | H12: ='Income Statement'!H9/'Income Statement'!H7 -> 0.38564671 | I12: ='Income Statement'!I9/'Income Statement'!I7 -> 0.38564671 | K12: 0.3782 | L12: Better
C13: Operating Profit Margin | D13: ='Income Statement'!D11/'Income Statement'!D7 -> 0.10337872 | E13: ='Income Statement'!E11/'Income Statement'!E7 -> 0.1254086 | F13: ='Income Statement'!F11/'Income Statement'!F7 -> 0.13338955 | G13: ='Income Statement'!G11/'Income Statement'!G7 -> 0.12072562 | H13: ='Income Statement'!H11/'Income Statement'!H7 -> 0.12072562 | I13: ='Income Statement'!I11/'Income Statement'!I7 -> 0.12072562 | K13: 0.0967 | L13: Better
C14: Net Profit Margin | D14: ='Income Statement'!D19/'Income Statement'!D7 -> 0.069369615 | E14: ='Income Statement'!E19/'Income Statement'!E7 -> 0.061374168 | F14: ='Income Statement'!F19/'Income Statement'!F7 -> 0.091761023 | G14: ='Income Statement'!G19/'Income Statement'!G7 -> 0.078335443 | H14: ='Income Statement'!H19/'Income Statement'!H7 -> 0.077014165 | I14: ='Income Statement'!I19/'Income Statement'!I7 -> 0.079248963 | K14: 0.0767 | L14: Better
B16: Return Ratios:
C17: Return on Equity | D17: ='Income Statement'!D19/AVERAGE('Balance Sheet'!D60:E60) -> 0.47084514 | E17: ='Income Statement'!E19/AVERAGE('Balance Sheet'!E60:F60) -> 0.32017032 | F17: ='Income Statement'!F19/AVERAGE('Balance Sheet'!F60:G60) -> 0.44379854 | G17: ='Income Statement'!G19/AVERAGE('Balance Sheet'!G60:H60) -> 0.33147989 | H17: ='Income Statement'!H19/AVERAGE('Balance Sheet'!H60:I60) -> 0.25441824 | I17: ='Income Statement'!I19/AVERAGE('Balance Sheet'!I60:J60) -> 0.21612193 | K17: 0.1229 | L17: Better
C18: Return on Capital Employed | D18: ='Income Statement'!D11/('Balance Sheet'!E26-'Balance Sheet'!E39) -> 0.22858705 | E18: ='Income Statement'!E11/('Balance Sheet'!F26-'Balance Sheet'!F39) -> 0.26096101 | F18: ='Income Statement'!F11/('Balance Sheet'!G26-'Balance Sheet'!G39) -> 0.23008923 | G18: ='Income Statement'!G11/('Balance Sheet'!H26-'Balance Sheet'!H39) -> 0.19961853 | H18: ='Income Statement'!H11/('Balance Sheet'!I26-'Balance Sheet'!I39) -> 0.18497284 | I18: ='Income Statement'!I11/('Balance Sheet'!J26-'Balance Sheet'!J39) -> 0.16997838
C19: Return on Invested Capital | D19: ='Income Statement'!D11*(1-'Income Statement'!D18)/('Balance Sheet'!E26-'Balance Sheet'!E39-'Balance Sheet'!E9) -> 0.18394435 | E19: ='Income Statement'!E11*(1-'Income Statement'!E18)/('Balance Sheet'!F26-'Balance Sheet'!F39-'Balance Sheet'!F9) -> 0.23855764 | F19: ='Income Statement'!F11*(1-'Income Statement'!F18)/('Balance Sheet'!G26-'Balance Sheet'!G39-'Balance Sheet'!G9) -> 0.23748811 | G19: ='Income Statement'!G11*(1-'Income Statement'!G18)/('Balance Sheet'!H26-'Balance Sheet'!H39-'Balance Sheet'!H9) -> 0.21285105 | H19: ='Income Statement'!H11*(1-'Income Statement'!H18)/('Balance Sheet'!I26-'Balance Sheet'!I39-'Balance Sheet'!I9) -> 0.202221 | I19: ='Income Statement'!I11*(1-'Income Statement'!I18)/('Balance Sheet'!J26-'Balance Sheet'!J39-'Balance Sheet'!J9) -> 0.19073239
C20: Return on Assets | D20: ='Income Statement'!D19/AVERAGE('Balance Sheet'!D26:E26) -> 0.1202379 | E20: ='Income Statement'!E19/AVERAGE('Balance Sheet'!E26:F26) -> 0.10211306 | F20: ='Income Statement'!F19/AVERAGE('Balance Sheet'!F26:G26) -> 0.13187246 | G20: ='Income Statement'!G19/AVERAGE('Balance Sheet'!G26:H26) -> 0.1022766 | H20: ='Income Statement'!H19/AVERAGE('Balance Sheet'!H26:I26) -> 0.096265022 | I20: ='Income Statement'!I19/AVERAGE('Balance Sheet'!I26:J26) -> 0.093243523 | K20: 0.0628 | L20: Better
B22: Liquidity Ratios:
C23: Current Ratio | D23: ='Balance Sheet'!E18/'Balance Sheet'!E39 -> 1.3763384 | E23: ='Balance Sheet'!F18/'Balance Sheet'!F39 -> 1.5624254 | F23: ='Balance Sheet'!G18/'Balance Sheet'!G39 -> 1.9398128 | G23: ='Balance Sheet'!H18/'Balance Sheet'!H39 -> 1.9330274 | H23: ='Balance Sheet'!I18/'Balance Sheet'!I39 -> 2.102548 | I23: ='Balance Sheet'!J18/'Balance Sheet'!J39 -> 2.3317492 | K23: 1.76x | L23: Better
C24: Quick/Liquid Ratio | D24: =('Balance Sheet'!E18-'Balance Sheet'!E15)/'Balance Sheet'!E39 -> 0.992377 | E24: =('Balance Sheet'!F18-'Balance Sheet'!F15)/'Balance Sheet'!F39 -> 1.267436 | F24: =('Balance Sheet'!G18-'Balance Sheet'!G15)/'Balance Sheet'!G39 -> 1.6882115 | G24: =('Balance Sheet'!H18-'Balance Sheet'!H15)/'Balance Sheet'!H39 -> 1.6634501 | H24: =('Balance Sheet'!I18-'Balance Sheet'!I15)/'Balance Sheet'!I39 -> 1.8378786 | I24: =('Balance Sheet'!J18-'Balance Sheet'!J15)/'Balance Sheet'!J39 -> 2.0627108 | K24: 1.17x | L24: Better
C25: Cash Ratio | D25: ='Balance Sheet'!E9/'Balance Sheet'!E39 -> 0.21835794 | E25: ='Balance Sheet'!F9/'Balance Sheet'!F39 -> 0.58210319 | F25: ='Balance Sheet'!G9/'Balance Sheet'!G39 -> 0.86494884 | G25: ='Balance Sheet'!H9/'Balance Sheet'!H39 -> 0.98649911 | H25: ='Balance Sheet'!I9/'Balance Sheet'!I39 -> 1.1310139 | I25: ='Balance Sheet'!J9/'Balance Sheet'!J39 -> 1.3119717 | K25: 0.53x | L25: Better
B27: Efficiency Ratios:
C28: Accounts Receivable Turnover Ratio | D28: ='Income Statement'!D7/AVERAGE('Balance Sheet'!D11:E11) -> 12.348605 | E28: ='Income Statement'!E7/AVERAGE('Balance Sheet'!E11:F11) -> 12.231581 | F28: ='Income Statement'!F7/AVERAGE('Balance Sheet'!F11:G11) -> 12.281598 | G28: ='Income Statement'!G7/AVERAGE('Balance Sheet'!G11:H11) -> 12.283496 | H28: ='Income Statement'!H7/AVERAGE('Balance Sheet'!H11:I11) -> 12.219719 | I28: ='Income Statement'!I7/AVERAGE('Balance Sheet'!I11:J11) -> 12.276993
C29: Accounts Receivable Turnover (Days) | D29: =365/D28 -> 29.557994 | E29: =365/E28 -> 29.840786 | F29: =365/F28 -> 29.719259 | G29: =365/G28 -> 29.714667 | H29: =365/H28 -> 29.869755 | I29: =365/I28 -> 29.730408
C30: Inventory Turnover Ratio | D30: ='Income Statement'!D8/AVERAGE('Balance Sheet'!D15:E15) -> 12.063429 | E30: ='Income Statement'!E8/AVERAGE('Balance Sheet'!E15:F15) -> 12.114373 | F30: ='Income Statement'!F8/AVERAGE('Balance Sheet'!F15:G15) -> 12.713063 | G30: ='Income Statement'!G8/AVERAGE('Balance Sheet'!G15:H15) -> 12.710822 | H30: ='Income Statement'!H8/AVERAGE('Balance Sheet'!H15:I15) -> 12.52261 | I30: ='Income Statement'!I8/AVERAGE('Balance Sheet'!I15:J15) -> 12.64826
C31: Inventory Turnover (Days) | D31: =365/D30 -> 30.256737 | E31: =365/E30 -> 30.1295 | F31: =365/F30 -> 28.710627 | G31: =365/G30 -> 28.715688 | H31: =365/H30 -> 29.147279 | I31: =365/I30 -> 28.857724 | K31: 73.82Days | L31: Better
